Traceback (most recent call last):
  File "/usr/lib/python3/dist-packages/mysql/connector/network.py", line 509, in open_connection
    self.sock.connect(sockaddr)
ConnectionRefusedError: [Errno 111] Connection refused

During handling of the above exception, another exception occurred:

Traceback (most recent call last):
  File "moodboard.py", line 10, in <module>
    db = mariadb.connect(user="dbuser", password="harvestmood", database="moods");
  File "/usr/lib/python3/dist-packages/mysql/connector/__init__.py", line 179, in connect
    return MySQLConnection(*args, **kwargs)
  File "/usr/lib/python3/dist-packages/mysql/connector/connection.py", line 94, in __init__
    self.connect(**kwargs)
  File "/usr/lib/python3/dist-packages/mysql/connector/abstracts.py", line 722, in connect
    self._open_connection()
  File "/usr/lib/python3/dist-packages/mysql/connector/connection.py", line 207, in _open_connection
    self._socket.open_connection()
  File "/usr/lib/python3/dist-packages/mysql/connector/network.py", line 512, in open_connection
    errno=2003, values=(self.get_address(), _strioerror(err)))
mysql.connector.errors.InterfaceError: 2003: Can't connect to MySQL server on '127.0.0.1:3306' (111 Connection refused)
